<?xml version="1.0" ?>
<!-- =================================================================================== -->
<!-- |    This document was autogenerated by xacro from astribot_s1_whole_body_without_wheel.xacro | -->
<!-- |    EDITING THIS FILE BY HAND IS NOT RECOMMENDED                                 | -->
<!-- =================================================================================== -->
<!-- run: xacro astribot_s1_whole_body.xacro -o astribot_s1_whole_body.urdf to generate the following .urdf file -->
<robot name="astribot_whole_body">
  <link name="astribot_torso_base">
    <inertial>
      <origin rpy="0 0 0" xyz="-0.062784 0.007017 0.035375"/>
      <mass value="39.24781"/>
      <inertia ixx="1.071997" ixy="0.015889" ixz="-0.058447" iyy="1.218431" iyz="-0.002015" izz="1.489411"/>
    </inertial>
    <visual>
      <origin rpy="0 0 0" xyz="0 0 0"/>
      <geometry>
        <mesh filename="s1_torso/astribot_torso_base_link.STL"/>
      </geometry>
      <material name="">
        <color rgba="0.79216 0.81961 0.93333 1"/>
      </material>
    </visual>
    <collision>
      <origin rpy="0 0 0" xyz="0 0 -0.05"/>
      <geometry>
        <cylinder length="0.1" radius="0.3"/>
      </geometry>
    </collision>
  </link>
  <link name="astribot_torso_link_1">
    <inertial>
      <origin rpy="0 0 0" xyz="-0.15249 0.00021066 -0.0033476"/>
      <mass value="7.3766"/>
      <inertia ixx="0.028834" ixy="-0.0052759" ixz="0.00010767" iyy="0.1483" iyz="1.1652E-05" izz="0.14268"/>
    </inertial>
    <visual>
      <origin rpy="0 0 0" xyz="0 0 0"/>
      <geometry>
        <mesh filename="s1_torso/astribot_torso_link_1.STL"/>
      </geometry>
      <material name="">
        <color rgba="0.89804 0.91765 0.92941 1"/>
      </material>
    </visual>
    <collision>
      <origin rpy="0 1.57 0" xyz="-0.15 0 0"/>
      <geometry>
        <cylinder length="0.3" radius="0.1"/>
      </geometry>
    </collision>
  </link>
  <joint name="astribot_torso_joint_1" type="revolute">
    <origin rpy="-1.5708 1.5708 0" xyz="0 0 0.12"/>
    <parent link="astribot_torso_base"/>
    <child link="astribot_torso_link_1"/>
    <axis xyz="0 0 1"/>
    <limit effort="100" lower="0.0" upper="1.4" velocity="6.0"/>
  </joint>
  <link name="astribot_torso_link_2">
    <inertial>
      <origin rpy="0 0 0" xyz="-0.22214 0.028873 0.00059024"/>
      <mass value="5.6183"/>
      <inertia ixx="0.0082545" ixy="0.0011523" ixz="0.00035614" iyy="0.012677" iyz="-5.8287E-05" izz="0.017512"/>
    </inertial>
    <visual>
      <origin rpy="0 0 0" xyz="0 0 0"/>
      <geometry>
        <mesh filename="s1_torso/astribot_torso_link_2.STL"/>
      </geometry>
      <material name="">
        <color rgba="0.89804 0.91765 0.92941 1"/>
      </material>
    </visual>
    <collision>
      <origin rpy="0 1.57 -0.25" xyz="-0.15 0.03 0"/>
      <geometry>
        <cylinder length="0.3" radius="0.1"/>
      </geometry>
    </collision>
  </link>
  <joint name="astribot_torso_joint_2" type="revolute">
    <origin rpy="0 0 0" xyz="-0.38 0 0"/>
    <parent link="astribot_torso_link_1"/>
    <child link="astribot_torso_link_2"/>
    <axis xyz="0 0 1"/>
    <limit effort="100" lower="-2.3" upper="0.0" velocity="6.0"/>
  </joint>
  <link name="astribot_torso_link_3">
    <inertial>
      <origin rpy="0 0 0" xyz="-0.017519 0.00059523 0.00025821"/>
      <mass value="0.49013"/>
      <inertia ixx="0.00022212" ixy="-2.6767E-07" ixz="4.3987E-07" iyy="0.00036522" iyz="3.8834E-07" izz="0.00038039"/>
    </inertial>
    <visual>
      <origin rpy="0 0 0" xyz="0 0 0"/>
      <geometry>
        <mesh filename="s1_torso/astribot_torso_link_3.STL"/>
      </geometry>
      <material name="">
        <color rgba="0.89804 0.91765 0.92941 1"/>
      </material>
    </visual>
    <collision>
      <origin rpy="0 1.57 0" xyz="-0.18 0.01 0"/>
      <geometry>
        <cylinder length="0.35" radius="0.09"/>
      </geometry>
    </collision>
  </link>
  <joint name="astribot_torso_joint_3" type="revolute">
    <origin rpy="0 0 0" xyz="-0.390 0 0"/>
    <parent link="astribot_torso_link_2"/>
    <child link="astribot_torso_link_3"/>
    <axis xyz="0 0 1"/>
    <limit effort="100" lower="0.0" upper="2.3" velocity="6.0"/>
  </joint>
  <link name="astribot_torso_link_4">
    <inertial>
      <origin rpy="0 0 0" xyz="0.00476227191516749 -4.56966810241128E-05 0.242912573510671"/>
      <mass value="3.55695635704638"/>
      <inertia ixx="0.0165768322563514" ixy="-9.94098112646385E-06" ixz="-0.000100011483384926" iyy="0.014904355097835" iyz="9.86752047032885E-07" izz="0.0110629318711333"/>
    </inertial>
    <visual>
      <origin rpy="0 0 0" xyz="0 0 0"/>
      <geometry>
        <mesh filename="s1_torso/astribot_torso_link_4.STL"/>
      </geometry>
      <material name="">
        <color rgba="0.898039215686275 0.917647058823529 0.929411764705882 1"/>
      </material>
    </visual>
  </link>
  <joint name="astribot_torso_joint_4" type="revolute">
    <origin rpy="1.5708 0 -1.5708" xyz="0 0 0"/>
    <parent link="astribot_torso_link_3"/>
    <child link="astribot_torso_link_4"/>
    <axis xyz="0 0 1"/>
    <limit effort="100" lower="-1.5" upper="1.5" velocity="6.0"/>
  </joint>
  <link name="astribot_torso_end_effector">
    <inertial>
      <origin rpy="0 0 0" xyz="0 0 0"/>
      <mass value="0"/>
      <inertia ixx="0" ixy="0" ixz="0" iyy="0" iyz="0" izz="0"/>
    </inertial>
  </link>
  <joint name="astribot_torso_end_effector_fixed_joint" type="fixed">
    <origin rpy="0.0 0.0 0.0" xyz="0 0 0.34475"/>
    <parent link="astribot_torso_link_4"/>
    <child link="astribot_torso_end_effector"/>
  </joint>
  <!-- <link name="astribot_head_base_link">
    <inertial>
      <origin rpy="0 0 0" xyz="-0.02816247 -0.00023176 -0.05211965"/>
      <mass value="0.39541440"/>
      <inertia ixx="0.00036025" ixy="-0.00003505" ixz="0.00004865" iyy="0.00049377" iyz="0.00000243" izz="0.00074441"/>
    </inertial>
    <visual>
      <origin rpy="0 0 0" xyz="0 0 0"/>
      <geometry>
        <mesh filename="s1_head/astribot_head_base_link.STL"/>
      </geometry>
      <material name="">
        <color rgba="0.807843137254902 0.843137254901961 0.905882352941176 1"/>
      </material>
    </visual>
  </link>
  <link name="astribot_head_link_1">
    <inertial>
      <origin rpy="0 0 0" xyz="0.00003191 -0.00038566 -0.02579910"/>
      <mass value="0.13910581"/>
      <inertia ixx="0.00004567" ixy="0.00000003" ixz="0.00000004" iyy="0.00004789" iyz="-0.00000091" izz="0.00003779"/>
    </inertial>
    <visual>
      <origin rpy="0 0 0" xyz="0 0 0"/>
      <geometry>
        <mesh filename="s1_head/astribot_head_link_1.STL"/>
      </geometry>
      <material name="">
        <color rgba="0.898039215686275 0.917647058823529 0.929411764705882 1"/>
      </material>
    </visual>
  </link>
  <joint name="astribot_head_joint_1" type="revolute">
    <origin rpy="0 0 0" xyz="0 0 0"/>
    <parent link="astribot_head_base_link"/>
    <child link="astribot_head_link_1"/>
    <axis xyz="0 0 1"/>
    <limit effort="100" lower="-1.57" upper="1.57" velocity="4.0"/>
  </joint>
  <link name="astribot_head_link_2">
    <inertial>
      <origin rpy="0 0 0" xyz="0.00705824 -0.14472601 -0.00061724"/>
      <mass value="0.97012447"/>
      <inertia ixx="0.00555660" ixy="-0.00041600" ixz="-0.00000036" iyy="0.00151908" iyz="-0.00012043" izz="0.00544493"/>
    </inertial>
    <visual>
      <origin rpy="0 0 0" xyz="0 0 0"/>
      <geometry>
        <mesh filename="s1_head/astribot_head_link_2.STL"/>
      </geometry>
      <material name="">
        <color rgba="0.807843137254902 0.843137254901961 0.905882352941176 1"/>
      </material>
    </visual>
    <collision>
      <origin rpy="0 0 0" xyz="0 -0.15 0"/>
      <geometry>
        <sphere radius="0.11"/>
      </geometry>
    </collision>
  </link>
  <joint name="astribot_head_joint_2" type="revolute">
    <origin rpy="-1.5708 0 0" xyz="0 0 0"/>
    <parent link="astribot_head_link_1"/>
    <child link="astribot_head_link_2"/>
    <axis xyz="0 0 1"/>
    <limit effort="100" lower="-1.22" upper="1.22" velocity="4.0"/>
  </joint> -->
  <link name="astribot_arm_left_base_link">
    <inertial>
      <origin rpy="0 0 0" xyz="-0.04309067 -0.01849796 -0.01384838"/>
      <mass value="2.22887320"/>
      <inertia ixx="0.00386389" ixy="-0.00050396" ixz="0.00025566" iyy="0.00306042" iyz="0.00019224" izz="0.00570294"/>
    </inertial>
    <visual>
      <origin rpy="0 0 0" xyz="0 0 0"/>
      <geometry>
        <mesh filename="s1_arm/astribot_arm_left_base_link.STL"/>
      </geometry>
      <material name="">
        <color rgba="0.898039215686275 0.917647058823529 0.929411764705882 1"/>
      </material>
    </visual>
  </link>
  <link name="astribot_arm_left_link_1">
    <inertial>
      <origin rpy="0 0 0" xyz="0.00012026 0.00047499 -0.05682561"/>
      <mass value="0.59936716"/>
      <inertia ixx="0.00064791" ixy="0.00000149" ixz="0.00000133" iyy="0.00065264" iyz="0.00000160" izz="0.00050137"/>
    </inertial>
    <visual>
      <origin rpy="0 0 0" xyz="0 0 0"/>
      <geometry>
        <mesh filename="s1_arm/astribot_arm_link_1.STL"/>
      </geometry>
      <material name="">
        <color rgba="0.898039215686275 0.917647058823529 0.929411764705882 1"/>
      </material>
    </visual>
  </link>
  <joint name="astribot_arm_left_joint_1" type="revolute">
    <origin rpy="0 0 0" xyz="0 0 0.091"/>
    <parent link="astribot_arm_left_base_link"/>
    <child link="astribot_arm_left_link_1"/>
    <axis xyz="0 0 1"/>
    <limit effort="265" lower="-3.0" upper="3.0" velocity="8.4"/>
  </joint>
  <link name="astribot_arm_left_link_2">
    <inertial>
      <origin rpy="0 0 0" xyz="-0.00396228 0.03490708 0.04270156"/>
      <mass value="1.43694657"/>
      <inertia ixx="0.00360751" ixy="-0.00009193" ixz="0.00007764" iyy="0.00283747" iyz="0.00054945" izz="0.00172927"/>
    </inertial>
    <visual>
      <origin rpy="0 0 0" xyz="0 0 0"/>
      <geometry>
        <mesh filename="s1_arm/astribot_arm_left_link_2.STL"/>
      </geometry>
      <material name="">
        <color rgba="0.698039215686274 0.698039215686274 0.698039215686274 1"/>
      </material>
    </visual>
  </link>
  <joint name="astribot_arm_left_joint_2" type="revolute">
    <origin rpy="1.5708 0 0" xyz="0 0 0"/>
    <parent link="astribot_arm_left_link_1"/>
    <child link="astribot_arm_left_link_2"/>
    <axis xyz="0 0 1"/>
    <limit effort="265" lower="-1.4" upper="0.4" velocity="8.4"/>
  </joint>
  <link name="astribot_arm_left_link_3">
    <inertial>
      <origin rpy="0 0 0" xyz="0.00531263 0.00020707 0.16136713"/>
      <mass value="2.0926399"/>
      <inertia ixx="0.01752179" ixy="2.336e-05" ixz="0.00144018" iyy="0.01784671" iyz="-3.027e-05" izz="0.0021843"/>
    </inertial>
    <visual>
      <origin rpy="0 0 0" xyz="0 0 0"/>
      <geometry>
        <mesh filename="s1_arm/astribot_arm_link_3.STL"/>
      </geometry>
      <material name="">
        <color rgba="0.698039215686274 0.698039215686274 0.698039215686274 1"/>
      </material>
    </visual>
    <collision>
      <origin rpy="0 0 0" xyz="0 0 0.15"/>
      <geometry>
        <cylinder length="0.18" radius="0.05"/>
      </geometry>
    </collision>
  </link>
  <joint name="astribot_arm_left_joint_3" type="revolute">
    <origin rpy="1.5708 0 -1.5708" xyz="0 0.05 0"/>
    <parent link="astribot_arm_left_link_2"/>
    <child link="astribot_arm_left_link_3"/>
    <axis xyz="0 0 1"/>
    <limit effort="132" lower="-3.0" upper="1.4" velocity="8.4"/>
  </joint>
  <link name="astribot_arm_left_link_4">
    <inertial>
      <origin rpy="0 0 0" xyz="0.00017294 -0.01269315 0.00196140"/>
      <mass value="0.36587933"/>
      <inertia ixx="0.00047693" ixy="0.00000635" ixz=" 0.00000135" iyy="0.00036801" iyz="0.00000705" izz="0.00050082"/>
    </inertial>
    <visual>
      <origin rpy="0 0 0" xyz="0 0 0"/>
      <geometry>
        <mesh filename="s1_arm/astribot_arm_link_4.STL"/>
      </geometry>
      <material name="">
        <color rgba="0.698039215686274 0.698039215686274 0.698039215686274 1"/>
      </material>
    </visual>
    <collision>
      <origin rpy="0 0 0" xyz="0 0 0"/>
      <geometry>
        <sphere radius="0.06"/>
      </geometry>
    </collision>
  </link>
  <joint name="astribot_arm_left_joint_4" type="revolute">
    <origin rpy="-1.5708 0 0" xyz="0.03 0 0.309"/>
    <parent link="astribot_arm_left_link_3"/>
    <child link="astribot_arm_left_link_4"/>
    <axis xyz="0 0 1"/>
    <limit effort="142" lower="0.0" upper="2.4" velocity="15"/>
  </joint>
  <link name="astribot_arm_left_link_5">
    <inertial>
      <origin rpy="0 0 0" xyz="-0.00032037 -0.00015185 0.15370447"/>
      <mass value="1.24085064"/>
      <inertia ixx="0.00454092" ixy="1.58e-06" ixz="-5.91e-06" iyy="0.00438922" iyz="-4.927e-05" izz="0.00079442"/>
    </inertial>
    <visual>
      <origin rpy="0 0 0" xyz="0 0 0"/>
      <geometry>
        <mesh filename="s1_arm/astribot_arm_link_5.STL"/>
      </geometry>
      <material name="">
        <color rgba="0.698039215686274 0.698039215686274 0.698039215686274 1"/>
      </material>
    </visual>
    <collision>
      <origin rpy="0 0 0" xyz="0 0 0.14"/>
      <geometry>
        <cylinder length="0.14" radius="0.05"/>
      </geometry>
    </collision>
  </link>
  <joint name="astribot_arm_left_joint_5" type="revolute">
    <origin rpy="1.5708 0 0" xyz="0 0 0"/>
    <parent link="astribot_arm_left_link_4"/>
    <child link="astribot_arm_left_link_5"/>
    <axis xyz="0 0 1"/>
    <limit effort="71" lower="-2.0" upper="2.0" velocity="15"/>
  </joint>
  <link name="astribot_arm_left_link_6">
    <inertial>
      <origin rpy="0 0 0" xyz="-0.00010311 0.00001218 0.00013181"/>
      <mass value="0.22465307"/>
      <inertia ixx="0.00016474" ixy="0.00000007" ixz="0.00000025" iyy="0.00015608" iyz="0.00000018" izz="0.00008555"/>
    </inertial>
    <visual>
      <origin rpy="0 0 0" xyz="0 0 0"/>
      <geometry>
        <mesh filename="s1_arm/astribot_arm_link_6.STL"/>
      </geometry>
      <material name="">
        <color rgba="0.698039215686274 0.698039215686274 0.698039215686274 1"/>
      </material>
    </visual>
  </link>
  <joint name="astribot_arm_left_joint_6" type="revolute">
    <origin rpy="-1.5708 0 0" xyz="0 0 0.277"/>
    <parent link="astribot_arm_left_link_5"/>
    <child link="astribot_arm_left_link_6"/>
    <axis xyz="0 0 1"/>
    <limit effort="20" lower="-0.6" upper="0.6" velocity="16.8"/>
  </joint>
  <link name="astribot_arm_left_link_7">
    <inertial>
      <origin rpy="0 0 0" xyz="4.333e-05 -0.00723447 -0.00362428"/>
      <mass value="0.12772019"/>
      <inertia ixx="0.00013672" ixy="1.6e-07" ixz="-2.4e-07" iyy="0.00010783" iyz="-3.35e-06" izz="5.858e-05"/>
    </inertial>
    <visual>
      <origin rpy="0 0 0" xyz="0 0 0"/>
      <geometry>
        <mesh filename="s1_arm/astribot_arm_link_7.STL"/>
      </geometry>
      <material name="">
        <color rgba="0.898039215686275 0.917647058823529 0.929411764705882 1"/>
      </material>
    </visual>
    <collision>
      <origin rpy="0 0 0" xyz="0.006 0 0"/>
      <geometry>
        <sphere radius="0.05"/>
      </geometry>
    </collision>
  </link>
  <joint name="astribot_arm_left_joint_7" type="revolute">
    <origin rpy="0 1.5708 0" xyz="0 0 0"/>
    <parent link="astribot_arm_left_link_6"/>
    <child link="astribot_arm_left_link_7"/>
    <axis xyz="0 0 1"/>
    <limit effort="20" lower="-1.4" upper="1.4" velocity="16.8"/>
  </joint>
  <link name="astribot_arm_left_tool_link">
    <inertial>
      <origin rpy="0 0 0" xyz=" -0.00019766 -0.10719761 0.00190898"/>
      <mass value="0.64762850"/>
      <inertia ixx="0.00152446" ixy="0.00000144" ixz="-0.00000058" iyy="0.00033076" iyz="0.00004144" izz="0.00156453"/>
    </inertial>
  </link>
  <joint name="astribot_arm_left_tool_joint" type="fixed">
    <origin rpy="0 0 0" xyz="0 0 0"/>
    <parent link="astribot_arm_left_link_7"/>
    <child link="astribot_arm_left_tool_link"/>
  </joint>
  <link name="astribot_arm_left_end_effector">
    <inertial>
      <origin rpy="0 0 0" xyz="0 0 0"/>
      <mass value="0"/>
      <inertia ixx="0" ixy="0" ixz="0" iyy="0" iyz="0" izz="0"/>
    </inertial>
  </link>
  <joint name="astribot_arm_left_ee_joint" type="fixed">
    <origin rpy="0 0 0" xyz="0 -0.15 0"/>
    <parent link="astribot_arm_left_tool_link"/>
    <child link="astribot_arm_left_end_effector"/>
  </joint>
  <link name="astribot_arm_right_base_link">
    <inertial>
      <origin rpy="0 0 0" xyz="-0.04450932 0.01988693 0.00162589"/>
      <mass value="2.22887320"/>
      <inertia ixx="0.00396811" ixy="0.00041290" ixz="-0.00033387" iyy="0.00304615" iyz="-0.00021572" izz="0.00574641"/>
    </inertial>
    <visual>
      <origin rpy="0 0 0" xyz="0 0 0"/>
      <geometry>
        <mesh filename="s1_arm/astribot_arm_right_base_link.STL"/>
      </geometry>
      <material name="">
        <color rgba="0.898039215686275 0.917647058823529 0.929411764705882 1"/>
      </material>
    </visual>
  </link>
  <link name="astribot_arm_right_link_1">
    <inertial>
      <origin rpy="0 0 0" xyz="0.00012026 0.00047499 -0.05682561"/>
      <mass value="0.59936716"/>
      <inertia ixx="0.00064791" ixy="0.00000149" ixz="0.00000133" iyy="0.00065264" iyz="0.00000160" izz="0.00050137"/>
    </inertial>
    <visual>
      <origin rpy="0 0 0" xyz="0 0 0"/>
      <geometry>
        <mesh filename="s1_arm/astribot_arm_link_1.STL"/>
      </geometry>
      <material name="">
        <color rgba="0.898039215686275 0.917647058823529 0.929411764705882 1"/>
      </material>
    </visual>
  </link>
  <joint name="astribot_arm_right_joint_1" type="revolute">
    <origin rpy="0 0 0" xyz="0 0 0.091"/>
    <parent link="astribot_arm_right_base_link"/>
    <child link="astribot_arm_right_link_1"/>
    <axis xyz="0 0 1"/>
    <limit effort="265" lower="-3.0" upper="3.0" velocity="8.4"/>
  </joint>
  <link name="astribot_arm_right_link_2">
    <inertial>
      <origin rpy="0 0 0" xyz="-0.00384709 0.03502105 -0.04050705"/>
      <mass value="1.45811037"/>
      <inertia ixx="0.00394196" ixy="-8.846e-05" ixz="-3.742e-05" iyy="0.00316298" iyz="-0.0007079" izz="0.00177295"/>
    </inertial>
    <visual>
      <origin rpy="0 0 0" xyz="0 0 0"/>
      <geometry>
        <mesh filename="s1_arm/astribot_arm_right_link_2.STL"/>
      </geometry>
      <material name="">
        <color rgba="0.698039215686274 0.698039215686274 0.698039215686274 1"/>
      </material>
    </visual>
  </link>
  <joint name="astribot_arm_right_joint_2" type="revolute">
    <origin rpy="1.5708 0 0" xyz="0 0 0"/>
    <parent link="astribot_arm_right_link_1"/>
    <child link="astribot_arm_right_link_2"/>
    <axis xyz="0 0 1"/>
    <limit effort="265" lower="-1.4" upper="0.4" velocity="8.4"/>
  </joint>
  <link name="astribot_arm_right_link_3">
    <inertial>
      <origin rpy="0 0 0" xyz="0.00531263 0.00020707 0.16136713"/>
      <mass value="2.0926399"/>
      <inertia ixx="0.01752179" ixy="2.336e-05" ixz="0.00144018" iyy="0.01784671" iyz="-3.027e-05" izz="0.0021843"/>
    </inertial>
    <visual>
      <origin rpy="0 0 0" xyz="0 0 0"/>
      <geometry>
        <mesh filename="s1_arm/astribot_arm_link_3.STL"/>
      </geometry>
      <material name="">
        <color rgba="0.698039215686274 0.698039215686274 0.698039215686274 1"/>
      </material>
    </visual>
    <collision>
      <origin rpy="0 0 0" xyz="0 0 0.15"/>
      <geometry>
        <cylinder length="0.18" radius="0.05"/>
      </geometry>
    </collision>
  </link>
  <joint name="astribot_arm_right_joint_3" type="revolute">
    <origin rpy="1.5708 0 -1.5708" xyz="0 0.05 0"/>
    <parent link="astribot_arm_right_link_2"/>
    <child link="astribot_arm_right_link_3"/>
    <axis xyz="0 0 1"/>
    <limit effort="132" lower="-1.4" upper="3.0" velocity="8.4"/>
  </joint>
  <link name="astribot_arm_right_link_4">
    <inertial>
      <origin rpy="0 0 0" xyz="0.00017294 -0.01269315 0.00196140"/>
      <mass value="0.36587933"/>
      <inertia ixx="0.00047693" ixy="0.00000635" ixz=" 0.00000135" iyy="0.00036801" iyz="0.00000705" izz="0.00050082"/>
    </inertial>
    <visual>
      <origin rpy="0 0 0" xyz="0 0 0"/>
      <geometry>
        <mesh filename="s1_arm/astribot_arm_link_4.STL"/>
      </geometry>
      <material name="">
        <color rgba="0.698039215686274 0.698039215686274 0.698039215686274 1"/>
      </material>
    </visual>
    <collision>
      <origin rpy="0 0 0" xyz="0 0 0"/>
      <geometry>
        <sphere radius="0.06"/>
      </geometry>
    </collision>
  </link>
  <joint name="astribot_arm_right_joint_4" type="revolute">
    <origin rpy="-1.5708 0 0" xyz="0.03 0 0.309"/>
    <parent link="astribot_arm_right_link_3"/>
    <child link="astribot_arm_right_link_4"/>
    <axis xyz="0 0 1"/>
    <limit effort="142" lower="0.0" upper="2.4" velocity="15"/>
  </joint>
  <link name="astribot_arm_right_link_5">
    <inertial>
      <origin rpy="0 0 0" xyz="-0.00032037 -0.00015185 0.15370447"/>
      <mass value="1.24085064"/>
      <inertia ixx="0.00454092" ixy="1.58e-06" ixz="-5.91e-06" iyy="0.00438922" iyz="-4.927e-05" izz="0.00079442"/>
    </inertial>
    <visual>
      <origin rpy="0 0 0" xyz="0 0 0"/>
      <geometry>
        <mesh filename="s1_arm/astribot_arm_link_5.STL"/>
      </geometry>
      <material name="">
        <color rgba="0.698039215686274 0.698039215686274 0.698039215686274 1"/>
      </material>
    </visual>
    <collision>
      <origin rpy="0 0 0" xyz="0 0 0.14"/>
      <geometry>
        <cylinder length="0.14" radius="0.05"/>
      </geometry>
    </collision>
  </link>
  <joint name="astribot_arm_right_joint_5" type="revolute">
    <origin rpy="1.5708 0 0" xyz="0 0 0"/>
    <parent link="astribot_arm_right_link_4"/>
    <child link="astribot_arm_right_link_5"/>
    <axis xyz="0 0 1"/>
    <limit effort="71" lower="-2.0" upper="2.0" velocity="15"/>
  </joint>
  <link name="astribot_arm_right_link_6">
    <inertial>
      <origin rpy="0 0 0" xyz="-0.00010311 0.00001218 0.00013181"/>
      <mass value="0.22465307"/>
      <inertia ixx="0.00016474" ixy="0.00000007" ixz="0.00000025" iyy="0.00015608" iyz="0.00000018" izz="0.00008555"/>
    </inertial>
    <visual>
      <origin rpy="0 0 0" xyz="0 0 0"/>
      <geometry>
        <mesh filename="s1_arm/astribot_arm_link_6.STL"/>
      </geometry>
      <material name="">
        <color rgba="0.698039215686274 0.698039215686274 0.698039215686274 1"/>
      </material>
    </visual>
  </link>
  <joint name="astribot_arm_right_joint_6" type="revolute">
    <origin rpy="-1.5708 0 0" xyz="0 0 0.277"/>
    <parent link="astribot_arm_right_link_5"/>
    <child link="astribot_arm_right_link_6"/>
    <axis xyz="0 0 1"/>
    <limit effort="20" lower="-0.6" upper="0.6" velocity="16.8"/>
  </joint>
  <link name="astribot_arm_right_link_7">
    <inertial>
      <origin rpy="0 0 0" xyz="4.333e-05 -0.00723447 -0.00362428"/>
      <mass value="0.12772019"/>
      <inertia ixx="0.00013672" ixy="1.6e-07" ixz="-2.4e-07" iyy="0.00010783" iyz="-3.35e-06" izz="5.858e-05"/>
    </inertial>
    <visual>
      <origin rpy="0 0 0" xyz="0 0 0"/>
      <geometry>
        <mesh filename="s1_arm/astribot_arm_link_7.STL"/>
      </geometry>
      <material name="">
        <color rgba="0.898039215686275 0.917647058823529 0.929411764705882 1"/>
      </material>
    </visual>
    <collision>
      <origin rpy="0 0 0" xyz="0.006 0 0"/>
      <geometry>
        <sphere radius="0.05"/>
      </geometry>
    </collision>
  </link>
  <joint name="astribot_arm_right_joint_7" type="revolute">
    <origin rpy="0 1.5708 0" xyz="0 0 0"/>
    <parent link="astribot_arm_right_link_6"/>
    <child link="astribot_arm_right_link_7"/>
    <axis xyz="0 0 1"/>
    <limit effort="20" lower="-1.4" upper="1.4" velocity="16.8"/>
  </joint>
  <link name="astribot_arm_right_tool_link">
    <inertial>
      <origin rpy="0 0 0" xyz=" -0.00019766 -0.10719761 0.00190898"/>
      <mass value="0.64762850"/>
      <inertia ixx="0.00152446" ixy="0.00000144" ixz="-0.00000058" iyy="0.00033076" iyz="0.00004144" izz="0.00156453"/>
    </inertial>
  </link>
  <joint name="astribot_arm_right_tool_joint" type="fixed">
    <origin rpy="0 0 0" xyz="0 0 0"/>
    <parent link="astribot_arm_right_link_7"/>
    <child link="astribot_arm_right_tool_link"/>
  </joint>
  <link name="astribot_arm_right_end_effector">
    <inertial>
      <origin rpy="0 0 0" xyz="0 0 0"/>
      <mass value="0"/>
      <inertia ixx="0" ixy="0" ixz="0" iyy="0" iyz="0" izz="0"/>
    </inertial>
  </link>
  <joint name="astribot_arm_right_ee_joint" type="fixed">
    <origin rpy="0 0 0" xyz="0 -0.15 0"/>
    <parent link="astribot_arm_right_tool_link"/>
    <child link="astribot_arm_right_end_effector"/>
  </joint>
  <!-- <joint name="astribot_head_fixed_joint" type="fixed">
    <parent link="astribot_torso_end_effector"/>
    <child link="astribot_head_base_link"/>
    <origin rpy="0 0 0" xyz="0 0 0.1229"/>
  </joint> -->
  <joint name="astribot_arm_left_base_fixed_joint" type="fixed">
    <parent link="astribot_torso_end_effector"/>
    <child link="astribot_arm_left_base_link"/>
    <origin rpy="0 -1.22173 -1.5707963" xyz="0 0.06449 0.02348"/>
  </joint>
  <joint name="astribot_arm_right_base_fixed_joint" type="fixed">
    <parent link="astribot_torso_end_effector"/>
    <child link="astribot_arm_right_base_link"/>
    <origin rpy="0 -1.22173 1.5707963" xyz="0 -0.06449 0.02348"/>
  </joint>
</robot>
